<?xml version='1.0' encoding='UTF-8'?>
<robot xmlns:xacro="http://www.ros.org/wiki/xacro" name="xMateCR18">
  <!-- Constants for robot dimensions -->
  <material name="black">
    <color rgba="0.0 0.0 0.0 1.0"/>
  </material>
  <material name="blue">
    <color rgba="0.0 0.0 0.8 1.0"/>
  </material>
  <material name="green">
    <color rgba="0.0 0.8 0.0 1.0"/>
  </material>
  <material name="grey">
    <color rgba="0.2 0.2 0.2 1.0"/>
  </material>
  <material name="orange">
    <color rgba="1.0 0.423529411765 0.0392156862745 1.0"/>
  </material>
  <material name="brown">
    <color rgba="0.870588235294 0.811764705882 0.764705882353 1.0"/>
  </material>
  <material name="red">
    <color rgba="0.8 0.0 0.0 1.0"/>
  </material>
  <material name="white">
    <color rgba="1.0 1.0 1.0 1.0"/>
  </material>
  <material name="Beige">
    <color rgba="1.0 0.784 0.5765 1.0"/>
  </material>
  <!-- Used for fixing robot to Gazebo 'base_link' -->
  <link name="world"/>
  <joint name="fixed" type="fixed">
    <parent link="world"/>
    <child link="xMateCR18_base"/>
  </joint>
  <!--base-->
  <link name="xMateCR18_base">
    <visual>
      <geometry>
        <mesh filename="package://rokae_description/meshes/xMateCR18/xMateCR18_base.stl" scale="0.001 0.001 0.001"/>
      </geometry>
      <origin rpy="0 0 0" xyz="0.0 0.0 0.0"/>
      <material name="white"/>
    </visual>
    <collision>
      <geometry>
        <mesh filename="package://rokae_description/meshes/xMateCR18/xMateCR18_base.stl" scale="0.001 0.001 0.001"/>
      </geometry>
      <origin rpy="0 0 0" xyz="0.0 0.0 0.0"/>
    </collision>
  </link>
  <joint name="xMateCR18_joint_1" type="revolute">
    <parent link="xMateCR18_base"/>
    <child link="xMateCR18_link1"/>
    <limit effort="436" lower="-3.0543" upper="3.0543" velocity="2.0943951023931953"/>
    <axis xyz="0 0 1"/>
    <origin rpy="0 0 0" xyz="0.0 0.0 0.0"/>
  </joint>
  <transmission name="tran1">
    <type>transmission_interface/SimpleTransmission</type>
    <joint name="xMateCR18_joint_7">
      <hardwareInterface>EffortJointInterface</hardwareInterface>
    </joint>
    <actuator name="motor1">
      <hardwareInterface>EffortJointInterface</hardwareInterface>
      <mechanicalReduction>1</mechanicalReduction>
    </actuator>
  </transmission>
  <!--link 1-->
  <link name="xMateCR18_link1">
    <visual>
      <geometry>
        <mesh filename="package://rokae_description/meshes/xMateCR18/xMateCR18_link1.stl" scale="0.001 0.001 0.001"/>
      </geometry>
      <origin rpy="0 0 0" xyz="0 0 0"/>
      <material name="white"/>
    </visual>
    <inertial>
      <mass value="9.762"/>
      <inertia ixx="0.13037779" ixy="0.00003839" ixz="0.00015469" iyy="0.10332618" iyz="0.03481509" izz="0.07160903"/>
      <origin rpy="0 0 0" xyz="-5.7e-05 0.039543999999999996 0.26109"/>
    </inertial>
    <collision>
      <geometry>
        <mesh filename="package://rokae_description/meshes/xMateCR18/xMateCR18_link1.stl" scale="0.001 0.001 0.001"/>
      </geometry>
      <origin rpy="0 0 0" xyz="0 0 0"/>
    </collision>
  </link>
  <joint name="xMateCR18_joint_2" type="revolute">
    <parent link="xMateCR18_link1"/>
    <child link="xMateCR18_link2"/>
    <limit effort="436" lower="-2.9671" upper="2.9671" velocity="2.0943951023931953"/>
    <axis xyz="0 1 0"/>
    <origin rpy="0 0 0" xyz="0.0 0.0 0.35"/>
  </joint>
  <transmission name="tran2">
    <type>transmission_interface/SimpleTransmission</type>
    <joint name="xmate_joint_2">
      <hardwareInterface>EffortJointInterface</hardwareInterface>
    </joint>
    <actuator name="motor2">
      <hardwareInterface>EffortJointInterface</hardwareInterface>
      <mechanicalReduction>1</mechanicalReduction>
    </actuator>
  </transmission>
  <!--link 2-->
  <link name="xMateCR18_link2">
    <visual>
      <geometry>
        <mesh filename="package://rokae_description/meshes/xMateCR18/xMateCR18_link2.stl" scale="0.001 0.001 0.001"/>
      </geometry>
      <origin rpy="0 0 0" xyz="0 0 0.0"/>
      <material name="white"/>
    </visual>
    <inertial>
      <mass value="11.884"/>
      <inertia ixx="0.64271076" ixy="0.00013731" ixz="-0.00003451" iyy="0.64056501" iyz="0.00024604" izz="0.05021876"/>
      <origin rpy="0 0 0" xyz="7.3e-05 0.169482 0.216155"/>
    </inertial>
    <collision>
      <geometry>
        <mesh filename="package://rokae_description/meshes/xMateCR18/xMateCR18_link2.stl" scale="0.001 0.001 0.001"/>
      </geometry>
      <origin rpy="0 0 0" xyz="0 0 0.0"/>
    </collision>
  </link>
  <joint name="xMateCR18_joint_3" type="revolute">
    <parent link="xMateCR18_link2"/>
    <child link="xMateCR18_link3"/>
    <limit effort="194" lower="-2.8798" upper="2.8798" velocity="3.141592653589793"/>
    <axis xyz="0 -1 0"/>
    <origin rpy="0 0 0" xyz="0.0 0.0 0.52"/>
  </joint>
  <transmission name="tran3">
    <type>transmission_interface/SimpleTransmission</type>
    <joint name="xmate_joint_3">
      <hardwareInterface>EffortJointInterface</hardwareInterface>
    </joint>
    <actuator name="motor3">
      <hardwareInterface>EffortJointInterface</hardwareInterface>
      <mechanicalReduction>1</mechanicalReduction>
    </actuator>
  </transmission>
  <!--link 3-->
  <link name="xMateCR18_link3">
    <visual>
      <geometry>
        <mesh filename="package://rokae_description/meshes/xMateCR18/xMateCR18_link3.stl" scale="0.001 0.001 0.001"/>
      </geometry>
      <origin rpy="0 0 0" xyz="0 0 0"/>
      <material name="white"/>
    </visual>
    <inertial>
      <mass value="4.659"/>
      <inertia ixx="0.05218042" ixy="-0.00000246" ixz="0.00000101" iyy="0.03753873" iyz="0.01436120" izz="0.02573444"/>
      <origin rpy="0 0 0" xyz="-3.4e-05 -0.05076 0.059953000000000006"/>
    </inertial>
    <collision>
      <geometry>
        <mesh filename="package://rokae_description/meshes/xMateCR18/xMateCR18_link3.stl" scale="0.001 0.001 0.001"/>
      </geometry>
      <origin rpy="0 0 0" xyz="0 0 0"/>
    </collision>
  </link>
  <joint name="xMateCR18_joint_4" type="revolute">
    <parent link="xMateCR18_link3"/>
    <child link="xMateCR18_link4"/>
    <limit effort="102" lower="-3.0543" upper="3.0543" velocity="3.141592653589793"/>
    <!--     lower="-3.0543" upper="3.0543" -->
    <axis xyz="0 0 1"/>
    <!--     <origin rpy="0 0 0" xyz=0.0 0.0 0.405/> -->
    <origin rpy="0 0 0" xyz="0.0 0.0 0.405"/>
  </joint>
  <transmission name="tran4">
    <type>transmission_interface/SimpleTransmission</type>
    <joint name="xmate_joint_4">
      <hardwareInterface>EffortJointInterface</hardwareInterface>
    </joint>
    <actuator name="motor4">
      <hardwareInterface>EffortJointInterface</hardwareInterface>
      <mechanicalReduction>1</mechanicalReduction>
    </actuator>
  </transmission>
  <!--link 4-->
  <link name="xMateCR18_link4">
    <visual>
      <geometry>
        <mesh filename="package://rokae_description/meshes/xMateCR18/xMateCR18_link4.stl" scale=".001 0.001 0.001"/>
      </geometry>
      <origin rpy="0 0 0" xyz="0.0 0.0 0.0"/>
      <material name="white"/>
    </visual>
    <inertial>
      <mass value="3.327"/>
      <inertia ixx="0.03811846" ixy="-0.00000008" ixz="0.00000244" iyy="0.03675348" iyz="0.00481172" izz="0.00702595"/>
      <origin rpy="0 0 0" xyz="3.9e-05 0.015016 -0.100244"/>
    </inertial>
    <collision>
      <geometry>
        <mesh filename="package://rokae_description/meshes/xMateCR18/xMateCR18_link4.stl" scale="0.001 0.001 0.001"/>
      </geometry>
      <origin rpy="0 0 0" xyz="0.0 0.0 0.0"/>
    </collision>
  </link>
  <joint name="xMateCR18_joint_5" type="revolute">
    <parent link="xMateCR18_link4"/>
    <child link="xMateCR18_link5"/>
    <limit effort="66" lower="-3.0543" upper="3.0543" velocity="3.141592653589793"/>
    <axis xyz="0 -1 0"/>
    <origin rpy="0 0 0" xyz="0.0 -0.15 0.0"/>
  </joint>
  <transmission name="tran5">
    <type>transmission_interface/SimpleTransmission</type>
    <joint name="xmate_joint_5">
      <hardwareInterface>EffortJointInterface</hardwareInterface>
    </joint>
    <actuator name="motor5">
      <hardwareInterface>EffortJointInterface</hardwareInterface>
      <mechanicalReduction>1</mechanicalReduction>
    </actuator>
  </transmission>
  <!--link 5-->
  <link name="xMateCR18_link5">
    <visual>
      <geometry>
        <mesh filename="package://rokae_description/meshes/xMateCR18/xMateCR18_link5.stl" scale="0.001 0.001 0.001"/>
      </geometry>
      <origin rpy="0 0 0" xyz="0 0 0"/>
      <material name="white"/>
    </visual>
    <inertial>
      <mass value="2.34"/>
      <inertia ixx="0.00953363" ixy="-0.00000282" ixz="0.00000824" iyy="0.00581555" iyz="0.00099717" izz="0.00692085"/>
      <origin rpy="0 0 0" xyz="-4.2999999999999995e-05 -0.031099 0.014133"/>
    </inertial>
    <collision>
      <geometry>
        <mesh filename="package://rokae_description/meshes/xMateCR18/xMateCR18_link5.stl" scale="0.001 0.001 0.001"/>
      </geometry>
      <origin rpy="0 0 0" xyz="0 0 0"/>
    </collision>
  </link>
  <joint name="xMateCR18_joint_6" type="revolute">
    <parent link="xMateCR18_link5"/>
    <child link="xMateCR18_link6"/>
    <limit effort="66" lower="-3.0543" upper="3.0543" velocity="3.141592653589793"/>
    <axis xyz="0 0 1"/>
    <origin rpy="0.0 0.0 0" xyz="0.0 0.0 0.127"/>
  </joint>
  <transmission name="tran6">
    <type>transmission_interface/SimpleTransmission</type>
    <joint name="xmate_joint_6">
      <hardwareInterface>EffortJointInterface</hardwareInterface>
    </joint>
    <actuator name="motor6">
      <hardwareInterface>EffortJointInterface</hardwareInterface>
      <mechanicalReduction>1</mechanicalReduction>
    </actuator>
  </transmission>
  <!--link 6-->
  <link name="xMateCR18_link6">
    <visual>
      <geometry>
        <mesh filename="package://rokae_description/meshes/xMateCR18/xMateCR18_link6.stl" scale="0.001 0.001 0.001"/>
      </geometry>
      <origin rpy="0 0 0" xyz="0.0 0.0 0.0"/>
      <material name="white"/>
    </visual>
    <inertial>
      <mass value="1.142"/>
      <inertia ixx="0.00217743" ixy="-0.00000018" ixz="-0.00000015" iyy="0.00218830" iyz="-0.00000570" izz="0.00125122"/>
      <origin rpy="0 0 0" xyz="1e-06 -0.000201 -0.049302"/>
    </inertial>
    <collision>
      <geometry>
        <mesh filename="package://rokae_description/meshes/xMateCR18/xMateCR18_link6.stl" scale="0.001 0.001 0.001"/>
      </geometry>
      <origin rpy="0 0 0" xyz="0.0 0.0 0.0"/>
    </collision>
  </link>
</robot>
